Workbook

Sheet 使用说明
A1: 第一版开发任务表使用说明
A2: 用于安排需求与功能的开发顺序，不替代OpenSpec、单功能开发规格或可执行测试用例。
A3: 项目 | B3: 规则说明 | C3: 建议操作 | D3: 注意事项
A4: 技术基线 | B4: 当前项目：D:\unity\UnityProject\stellar-frontier-auto-era；框架来源：AI-Friendly-Project；产品业务不得写入ScriptsBuiltin。 | C4: 按任务ID持续维护 | D4: 不要跳过依赖和阶段验收门
A5: 开始任务 | B5: 确认所有前置依赖已完成；若需求规则尚未转为开发规格，应先补齐规格和对应测试用例。 | C5: 按任务ID持续维护 | D5: 不要跳过依赖和阶段验收门
A6: 并行方式 | B6: 不同工作流在依赖满足后可以并行；个人开发时可将其理解为可安全切换的独立任务，而非必须同时进行。 | C6: 按任务ID持续维护 | D6: 不要跳过依赖和阶段验收门
A7: 美术并行 | B7: 风格探索、场景方案、正式资源、动画、VFX和UI视觉可在独立美术项目中并行制作；通过资源包验收后再导回主工程。 | C7: 按ART任务和美术验收门持续维护 | D7: 美术生产不阻塞程序灰盒，但G8最终验收必须等待ART-G2通过
A8: 工时规则 | B8: 最低/最高工时为预计区间；任何任务一旦重新估算超过18小时，必须拆分后再开始。 | C8: 按任务ID持续维护 | D8: 不要跳过依赖和阶段验收门
A9: 完成规则 | B9: 任务达到完成定义（DoD）后才能标记已完成；阶段验收任务通过后才能正式进入下一关键阶段。 | C9: 按任务ID持续维护 | D9: 不要跳过依赖和阶段验收门
A10: 状态维护 | B10: 在“开发任务”表修改状态、实际工时和备注；状态列已经设置下拉选项。 | C10: 按任务ID持续维护 | D10: 不要跳过依赖和阶段验收门
A11: 测试边界 | B11: 本工作簿没有提前生成测试用例。测试用例应在具体需求进入开发前按最新规格创建。 | C11: 按任务ID持续维护 | D11: 不要跳过依赖和阶段验收门
A12: 本次授权 | B12: 2026-09-10用户明确授权本次设计审查后更新任务表；不构成长期xlsx修改授权或开发开工。

Sheet 开发任务
A1: 任务ID | B1: 阶段 | C1: 里程碑 | D1: 工作流 | E1: 模块 | F1: 任务名称 | G1: 任务说明 | H1: 优先级 | I1: 前置依赖 | J1: 并行组 | K1: 最低工时 | L1: 最高工时 | M1: 估算置信度 | N1: 预算分类 | O1: 完成定义（DoD） | P1: 状态 | Q1: 实际工时 | R1: 备注
A2: P0-001 | B2: 阶段0 工程准备 | C2: G0 工程基线 | D2: 配置与内容 | E2: 范围管理 | F2: 建立第一版开发基线 | G2: 以AI-Friendly-Project为母框架，登记冻结范围、排除项、设计来源和框架边界。 | H2: P0 | I2: 无 | J2: A0 | K2: 2 | L2: 4 | M2: 高 | N2: 程序预算 | O2: 开发入口能定位正式设计来源，并声明ScriptsBuiltin不可承载产品业务。 | P2: 已完成 | Q2: 0.5h
A3: P0-002 | B3: 阶段0 工程准备 | C3: G0 工程基线 | D3: 客户端程序 | E3: 工程结构 | F3: 建立自动纪元项目层目录与命名空间 | G3: 在 Assets/Game/Scripts/AutoEra 下建立产品代码边界，统一使用 AutoEra.* C# 命名空间；产品资源沿用既有资源类型根目录并按业务类别组织，不重复建立 AutoEra 资源目录层；GameData 按框架数据接入规则和业务类别组织；不修改 Assets/Game/ScriptsBuiltin。 | H3: P0 | I3: P0-001 | J3: A0 | K3: 4 | L3: 8 | M3: 高 | N3: 程序预算 | O3: 产品业务代码位于 Assets/Game/Scripts/AutoEra 并使用 AutoEra.* 命名空间；产品资源和 GameData 按既有类型根目录及业务类别组织，无冗余项目名称目录层；框架纯度审计不报告产品业务写入 ScriptsBuiltin 或其他边界越界。 | P3: 已完成 | Q3: 0.5h
A4: P0-003 | B4: 阶段0 工程准备 | C4: G0 工程基线 | D4: 客户端程序 | E4: 启动流程 | F4: 接入框架启动Procedure与业务场景 | G4: 实现IFrameworkStartupProcedure，从Launch／FrameworkReady切换到主菜单和第一版场景。 | H4: P0 | I4: P0-002 | J4: A0 | K4: 6 | L4: 10 | M4: 中 | N4: 程序预算 | O4: 始终从Launch进入，AppConfigs只注册一个业务启动Procedure，重复进出不残留状态。 | P4: 已完成
A5: P0-004 | B5: 阶段0 工程准备 | C5: G0 工程基线 | D5: 客户端程序 | E5: 基础设施 | F5: 建立永久实例ID与对象注册表 | G5: 统一机器、建筑、资源点、任务和行为实例的永久标识。 | H5: P0 | I5: P0-002 | J5: A0 | K5: 8 | L5: 14 | M5: 中 | N5: 程序预算 | O5: 对象生成、回收和重新载入后引用不会串到其他实例。 | P5: 已完成
A6: P0-005 | B6: 阶段0 工程准备 | C6: G0 工程基线 | D6: 客户端程序 | E6: 基础设施 | F6: 建立确定性世界时钟 | G6: 提供世界时间、昼夜阶段和可供在线／离线共同使用的推进接口。 | H6: P0 | I6: P0-002 | J6: A0 | K6: 8 | L6: 14 | M6: 中 | N6: 程序预算 | O6: 世界时间持续推进且不受界面打开影响，同刻事件可稳定排序。 | P6: 已完成
A7: P0-006 | B7: 阶段0 工程准备 | C7: G0 工程基线 | D7: 客户端程序 | E7: 配置系统 | F7: 接入项目DataTable／Config／Language | G7: 在GameData项目命名空间建立领域表，使用现有生成器并登记AppConfigs加载列表。 | H7: P0 | I7: P0-002 | J7: A0 | K7: 8 | L7: 14 | M7: 中 | N7: 程序预算 | O7: GF.DataTable／Config／Localization可读取项目数据，缺字段、重复ID和非法引用明确报错。 | P7: 已完成
A8: P0-007 | B8: 阶段0 工程准备 | C8: G0 工程基线 | D8: 客户端程序 | E8: 事件记录 | F8: 建立项目事件与责任追踪基础 | G8: 在GF_X事件机制上为任务、算法、效应器、资源和警报提供关联ID。 | H8: P0 | I8: P0-004 | J8: A0 | K8: 10 | L8: 16 | M8: 低 | N8: 程序预算 | O8: 命令、查询与事实事件边界明确，一次触发可追溯到来源与最终结果。 | P8: 已完成
A9: P0-008 | B9: 阶段0 工程准备 | C9: G0 工程基线 | D9: UI与交互 | E9: UI框架 | F9: 基于UIFormBase建立第一版UI层级 | G9: 沿用已验收ART-006与UIForm接入，承载HUD、现场面板、中枢管理界面及模态层；不重做视觉。 | H9: P0 | I9: P0-003,P0-006 | J9: A0 | K9: 10 | L9: 16 | M9: 中 | N9: 程序预算 | O9: 界面均由GF.UI打开，Esc层级正确，世界不因UIForm打开而暂停。 | P9: 已完成 | R9: 2026-09-10设计同步，未据此变更实现状态。
A10: P0-009 | B10: 阶段0 工程准备 | C10: G0 工程基线 | D10: 客户端程序 | E10: 输入与镜头 | F10: 建立项目InputModule并接入PC镜头 | G10: 实现可替换输入Provider，统一处理WASD、旋转、缩放、聚焦、Esc与UI拦截。 | H10: P0 | I10: P0-003 | J10: A0 | K10: 12 | L10: 18 | M10: 低 | N10: 程序预算 | O10: 产品层不直接读取UnityEngine.Input，所有语义输入均经过项目InputModule。 | P10: 已完成 | R10: 框架仅提供UI关闭接点，项目必须补充完整输入抽象。
A11: P0-010 | B11: 阶段0 工程准备 | C11: G0 工程基线 | D11: 灰盒与预制体 | E11: 制作规范 | F11: 建立EntityBase逻辑根与视觉子对象模板 | G11: 使用实体分组与对象池规范制作机器、建筑和资源点根预制体及锚点。 | H11: P0 | I11: P0-002,P0-006 | J11: A0 | K11: 6 | L11: 10 | M11: 高 | N11: 美术资源预算 | O11: 实体由GF.Entity管理，正式视觉可替换而ID、碰撞、锚点和玩法组件不变。 | P11: 已完成
A12: P0-011 | B12: 阶段0 工程准备 | C12: G0 工程基线 | D12: 配置与内容 | E12: 初始配置 | F12: 录入第一版基础配置骨架 | G12: 在项目DataTable中建立对象ID、分类、等级、能力、UI、实体和声音引用。 | H12: P0 | I12: P0-006 | J12: A0 | K12: 8 | L12: 14 | M12: 中 | N12: 程序预算 | O12: 所有第一版对象均能由GF数据组件查询且没有悬空资源引用。 | P12: 已完成
A13: P0-012 | B13: 阶段0 工程准备 | C13: G0 工程基线 | D13: 客户端程序 | E13: 框架接入 | F13: 接入项目UI、实体与声音分组 | G13: 扩展UITable、EntityGroupTable与SoundGroupTable并验证安全降级。 | H13: P0 | I13: P0-006,P0-010 | J13: A0 | K13: 6 | L13: 10 | M13: 中 | N13: 程序预算 | O13: 项目UI、实体和声音能够按配置加载，无资源时不会阻断启动。 | P13: 已完成
A14: P0-013 | B14: 阶段0 工程准备 | C14: G0 工程基线 | D14: 集成与阶段验收 | E14: 框架审计 | F14: 建立项目层编译与框架纯度检查入口 | G14: 记录编译、引用、AppConfigs、资源表和audit_framework_purity的检查方式。 | H14: P0 | I14: P0-002,P0-003,P0-006,P0-012 | J14: A0 | K14: 4 | L14: 8 | M14: 高 | N14: 程序预算 | O14: 项目业务不进入ScriptsBuiltin，框架纯度与启动诊断均可重复执行。 | P14: 已完成
A15: P0-014 | B15: 并行美术0 视觉预研 | C15: ART-G0 视觉基线 | D15: 客户端程序 | E15: 程序化动作 | F15: 实现程序化动作核心与配置模型 | G15: 实现MotionRig、MotionGraphAsset、强类型参数、稳定节点ID、基础运动原语、顺序／并行／循环／条件组合、集中式MotionExecutor、关节通道所有权和中断策略。 | H15: P0 | I15: P0-002,ART-005 | J15: ART-MOTION-TOOL | K15: 14 | L15: 18 | M15: 中 | N15: 程序预算 | O15: Core不依赖GF_X或具体玩法组件；EditMode覆盖配置校验、组合执行、取消恢复和版本迁移；运行热路径无持续GC分配。 | P15: 已完成 | R15: 可视化节点编辑器不在本任务范围；程序集与Hotfix、HybridCLR、FSR边界须在OpenSpec确认后实施。
A16: P0-015 | B16: 并行美术0 视觉预研 | C16: ART-G0 视觉基线 | D16: 客户端程序 | E16: 动作工具 | F16: 建立动作预览、校验与工具包发布链 | G16: 实现Inspector配置、EditMode／PlayMode预览、关节范围Gizmo、模拟参数上下文、静态校验、版本元数据及固定GUID的unitypackage发布流程。 | H16: P0 | I16: P0-014 | J16: ART-MOTION-TOOL | K16: 12 | L16: 18 | M16: 低 | N16: 程序预算 | O16: ArtResource可安装版本化Core与Editor工具包并预览同一动作资产；缺失关节、参数类型错误、通道冲突和非法连接能够在导出前明确报错。 | P16: 已完成 | R16: 工具包不包含AutoEra Adapter和玩法代码；可视化节点编辑器待代表性样机后决定。
A17: P0-016 | B17: 并行美术0 视觉预研 | C17: ART-G0 视觉基线 | D17: 集成与阶段验收 | E17: 动作贯通 | F17: 完成代表性机器程序动作贯通 | G17: 使用轮式载体、多关节机械臂和可替换效应器，验证待机、移动、转向、瞄准、作业、取消、断电、安全收回、恢复、对象池复用、重进场景和表现LOD。 | H17: P0 | I17: P0-010,P0-012,P0-015,ART-031 | J17: ART-PILOT | K17: 12 | L17: 18 | M17: 中 | N17: 程序预算 | O17: 美术项目预览与主工程真实状态驱动结果一致；固定GUID、MotionRig绑定和动作资产引用不丢失；停止更新后可从当前玩法状态正确恢复。 | P17: 已完成 | R17: 玩法逻辑拥有结算权威；动作表现不得反向决定产出、任务完成或存档结果。
A18: G0-001 | B18: 阶段0 工程准备 | C18: G0 工程基线 | D18: 集成与阶段验收 | E18: 阶段验收 | F18: 工程基线验收 | G18: 确认Launch启动、Procedure、时间、InputModule、GF.UI、GF.Entity和项目数据共同运行。 | H18: P0 | I18: P0-003,P0-004,P0-005,P0-006,P0-008,P0-009,P0-010,P0-011,P0-012,P0-013 | J18: G0 | K18: 6 | L18: 10 | M18: 高 | N18: 程序预算 | O18: 从Launch进入空业务场景，输入与UI正常，实体可加载，项目表无阻塞错误且未改框架核心。 | P18: 未开始
A19: P1-001 | B19: 阶段1 世界与对象 | C19: G1 可交互世界 | D19: 客户端程序 | E19: 区域 | F19: 建立初始区域与三类友方对象基类 | G19: 实现区域、机器、建筑和资源点的共同身份与公开状态边界。 | H19: P0 | I19: G0-001 | J19: A1 | K19: 10 | L19: 16 | M19: 中 | N19: 程序预算 | O19: 三类对象可注册到区域并通过统一入口取得其公开摘要。 | P19: 已完成 | R19: B10初始区域与三类友方对象基类已交付
A20: P1-002 | B20: 阶段1 世界与对象 | C20: G1 可交互世界 | D20: 客户端程序 | E20: 选择交互 | F20: 实现世界对象选择与现场判定 | G20: 实现左键选择、空白取消、选中轮廓、镜头距离和画面可见性判定。 | H20: P0 | I20: P0-009,P1-001 | J20: A1 | K20: 10 | L20: 16 | M20: 中 | N20: 程序预算 | O20: 只能选择有效对象，现场操作权限随镜头条件稳定切换。 | P20: 已完成 | R20: B10世界对象选择与现场判定已交付
A21: P1-003 | B21: 阶段1 世界与对象 | C21: G1 可交互世界 | D21: UI与交互 | E21: 现场界面 | F21: 实现对象现场侧栏通用框架 | G21: 提供概况、状态、规则按钮、定位及对象专属页签承载区。 | H21: P0 | I21: P0-008,P1-001,P1-002 | J21: A1 | K21: 10 | L21: 16 | M21: 中 | N21: 程序预算 | O21: 选中三类对象均能打开对应现场面板且不混用错误字段。 | P21: 已完成 | R21: B10对象现场侧栏通用框架已交付
A22: P1-004 | B22: 阶段1 世界与对象 | C22: G1 可交互世界 | D22: 客户端程序 | E22: 建造网格 | F22: 实现占地、位置与旋转吸附 | G22: 实现0.5米位置吸附、15度旋转吸附和占地冲突预览。 | H22: P0 | I22: P1-001 | J22: A1 | K22: 10 | L22: 16 | M22: 中 | N22: 程序预算 | O22: 预览能区分合法／非法位置，确认后对象占地与导航边界一致。 | P22: 已完成 | R22: B10占地/位置/旋转吸附已交付
A23: P1-005 | B23: 阶段1 世界与对象 | C23: G1 可交互世界 | D23: 客户端程序 | E23: 作业点 | F23: 实现作业点申请与等待队列 | G23: 区分可申请作业点、玩家物流点与等待队列；矿脉只校验机器位于有效作业区域并停稳，不要求玩家指定钻探点。 | H23: P0 | I23: P1-001,P0-004 | J23: A1 | K23: 10 | L23: 16 | M23: 低 | N23: 程序预算 | O23: 多个机器竞争同一点时不会重叠作业或重复寻路，释放后按序接替。 | P23: 已完成 | R23: 审计完成：申请/排队/占用/释放/取消/销毁对称路径已被4个测试文件覆盖；补2个真实缺口(等待者优先级升级+MotionWorkBridge WorkState跟随队列)；回归InitialRegion6/6+MotionWorkBridge5/5+MachineRegionIdentity13/13+MachineNavigation15/15+QA边界4/4全绿
A24: P1-006 | B24: 阶段1 世界与对象 | C24: G1 可交互世界 | D24: 灰盒与预制体 | E24: 场景灰盒 | F24: 搭建初始区域地形与对象占地区 | G24: 初始区域固定，布局农田、人工林、地表矿脉、无限水域与基地建筑；其它区域随机生成属于后续范围。 | H24: P0 | I24: P0-010 | J24: A1 | K24: 10 | L24: 16 | M24: 中 | N24: 美术资源预算 | O24: 场景比例符合1单位＝1米，通道允许轮式机器正常通行。 | P24: 已完成 | R24: B10初始区域地形与对象占地区已交付
A25: P1-007 | B25: 阶段1 世界与对象 | C25: G1 可交互世界 | D25: 灰盒与预制体 | E25: 资源点灰盒 | F25: 制作四类资源点灰盒预制体 | G25: 农田逐土地单元、人工林逐树、矿脉地表表现、无限水域四类资源点；边缘暂存区不等于玩家物流点。 | H25: P0 | I25: P0-010 | J25: A1 | K25: 12 | L25: 18 | M25: 中 | N25: 美术资源预算 | O25: 矿脉可通行但耗尽后的下次游戏内换日才释放建造占用；水域不自行产水。 | P25: 已完成 | R25: B10四类资源点灰盒预制体已交付
A26: P1-008 | B26: 阶段1 世界与对象 | C26: G1 可交互世界 | D26: 灰盒与预制体 | E26: 建筑灰盒 | F26: 制作基础建筑灰盒预制体 | G26: 制作仓库、工坊、发电机、太阳能、蓄电池及岸边水泵灰盒；静态外壳与必要接口，不新增内部机械。 | H26: P1 | I26: P0-010 | J26: A1 | K26: 12 | L26: 18 | M26: 中 | N26: 美术资源预算 | O26: 五类建筑占地、选择体、状态锚点和物流锚点符合规格。 | P26: 已完成 | R26: B10基础建筑灰盒预制体已交付
A27: P1-009 | B27: 阶段1 世界与对象 | C27: G1 可交互世界 | D27: UI与交互 | E27: HUD | F27: 实现基础HUD与对象聚焦 | G27: 显示世界时间、全局资源占位、任务／警报入口和当前选择摘要。 | H27: P0 | I27: P0-008,P0-005,P1-002 | J27: A1 | K27: 10 | L27: 16 | M27: 中 | N27: 程序预算 | O27: HUD持续刷新但不会抢走输入焦点，F可聚焦当前对象。 | P27: 已完成 | R27: B10/B11基础HUD与对象聚焦已交付
A28: G1-001 | B28: 阶段1 世界与对象 | C28: G1 可交互世界 | D28: 集成与阶段验收 | E28: 阶段验收 | F28: 可交互世界验收 | G28: 确认对象选择、现场面板、灰盒比例、占地和作业点能够闭环。 | H28: P0 | I28: P1-002,P1-003,P1-004,P1-005,P1-006,P1-007,P1-009 | J28: G1 | K28: 4 | L28: 8 | M28: 高 | N28: 程序预算 | O28: 玩家能在初始区域选择三类对象、查看现场信息并预览合法建造位置。 | P28: 未开始
A29: P2-001 | B29: 阶段2 机器运行 | C29: G2 机器可运行 | D29: 客户端程序 | E29: 机器载体 | F29: 实现轮式载体实例与唯一命名 | G29: 实现型号＋终身序号默认名、重命名、货舱和结构字段。 | H29: P0 | I29: P1-001,P0-004,P0-011 | J29: A2 | K29: 8 | L29: 14 | M29: 中 | N29: 程序预算 | O29: 每台机器名称唯一，回收后序号不复用，重命名可持久保留。 | P29: 已完成 | R29: B11/B12轮式载体实例与唯一命名已交付
A30: P2-002 | B30: 阶段2 机器运行 | C30: G2 机器可运行 | D30: 客户端程序 | E30: 组件槽位 | F30: 实现传感器、效应器与核心槽位 | G30: 支持兼容检查、安装、拆卸及已安装组件引用。 | H30: P0 | I30: P2-001,P0-011 | J30: A2 | K30: 12 | L30: 18 | M30: 中 | N30: 程序预算 | O30: 轮式载体可正确承载2传感器、2效应器和1核心，非法安装被拒绝。 | P30: 已完成 | R30: B11/B14传感器/效应器/核心槽位已交付
A31: P2-003 | B31: 阶段2 机器运行 | C31: G2 机器可运行 | D31: 客户端程序 | E31: 机器状态 | F31: 实现激活、休眠、开机、断电和连接 | G31: 按现场／中枢权限处理激活、运行、供电与中枢连接状态。 | H31: P0 | I31: P2-001,P2-002 | J31: A2 | K31: 12 | L31: 18 | M31: 低 | N31: 程序预算 | O31: 状态组合符合规则，断电恢复不丢配置且连接能自动重新判断。 | P31: 已完成 | R31: B11激活/休眠/开机/断电/连接已交付
A32: P2-004 | B32: 阶段2 机器运行 | C32: G2 机器可运行 | D32: 客户端程序 | E32: 任务队列 | F32: 实现机器五档优先级任务队列 | G32: 支持排队、正在处理、取消、完成、失败和同级FIFO。 | H32: P0 | I32: P0-004,P0-007,P2-001 | J32: A2 | K32: 12 | L32: 18 | M32: 低 | N32: 程序预算 | O32: 任务状态可追踪，队列满时拒绝新任务而不覆盖旧任务。 | P32: 已完成 | R32: B11五档优先级任务队列已交付
A33: P2-005 | B33: 阶段2 机器运行 | C33: G2 机器可运行 | D33: 客户端程序 | E33: 效应器队列 | F33: 实现每效应器独立行为队列 | G33: 支持安全中断点、抢占请求和行为结果返回。 | H33: P0 | I33: P2-004,P2-002 | J33: A2 | K33: 12 | L33: 18 | M33: 低 | N33: 程序预算 | O33: 不同效应器可并行，同一效应器严格串行且只在安全点切换。 | P33: 已完成 | R33: B11每效应器独立行为队列已交付
A34: P2-006 | B34: 阶段2 机器运行 | C34: G2 机器可运行 | D34: 客户端程序 | E34: 算力 | F34: 实现算力池、逻辑容量与默认调度 | G34: 实现持续占用、瞬时请求、排队、合并和不可执行结果。 | H34: P0 | I34: P2-002,P2-004 | J34: A2 | K34: 12 | L34: 18 | M34: 低 | N34: 程序预算 | O34: 一级核心能正确限制模板容量和运行并发，算力等待不会随机失败。 | P34: 已完成 | R34: B11算力池/逻辑容量/默认调度已交付
A35: P2-007 | B35: 阶段2 机器运行 | C35: G2 机器可运行 | D35: 客户端程序 | E35: 传感器 | F35: 实现传感器基类与绑定目标读取 | G35: 基础土壤传感器输出全量土地格网ID、坐标、面积与湿度；对象状态传感器提供同ID的适宜度与生长速度，保留范围和有效性。 | H35: P0 | I35: P2-002,P1-001,P2-006 | J35: A2 | K35: 12 | L35: 18 | M35: 低 | N35: 程序预算 | O35: 传感器只读取绑定目标的允许信息，休眠或离距后状态明确失效。 | P35: 已完成 | R35: B14传感器基类与绑定目标读取已交付
A36: P2-008 | B36: 阶段2 机器运行 | C36: G2 机器可运行 | D36: 客户端程序 | E36: 导航 | F36: 实现轮式机器自动寻路与基础避障 | G36: 接入NavMesh，处理目标点申请、移动算力、重规划和阻塞结果。 | H36: P0 | I36: P1-005,P2-001,P2-004,P2-006 | J36: A2 | K36: 12 | L36: 18 | M36: 低 | N36: 程序预算 | O36: 机器可自主抵达作业点，3／10／30秒规则正确产生重规划、警告和失败。 | P36: 已完成 | R36: B13轮式自动寻路与基础避障已交付
A37: P2-009 | B37: 阶段2 机器运行 | C37: G2 机器可运行 | D37: UI与交互 | E37: 机器现场UI | F37: 实现机器概况与硬件页 | G37: 显示状态、槽位、组件、功率、算力、命名和现场操作。 | H37: P0 | I37: P1-003,P2-002,P2-003,P2-006 | J37: A2 | K37: 12 | L37: 18 | M37: 中 | N37: 程序预算 | O37: 玩家可在现场完成激活、命名、安装拆卸及状态切换。 | P37: 已完成 | R37: B11机器概况与硬件页已交付
A38: P2-010 | B38: 阶段2 机器运行 | C38: G2 机器可运行 | D38: UI与交互 | E38: 中枢机器UI | F38: 实现中枢机器列表与状态摘要 | G38: 显示已连接机器、运行、任务、算力和警报并支持允许的远程操作。 | H38: P1 | I38: P0-008,P2-003,P2-004,P2-006 | J38: A2 | K38: 10 | L38: 16 | M38: 中 | N38: 程序预算 | O38: 中枢只显示已连接机器且不提供现场限定的硬件操作。 | P38: 已完成 | R38: 中枢机器索引只列已部署机器(库中蓝图移出)+运行时详情(任务/算力/导航/算法实例)已接入；MachineReadModel 12/12；总览页三栏聚合属P6-009
A39: P2-011 | B39: 阶段2 机器运行 | C39: G2 机器可运行 | D39: 灰盒与预制体 | E39: 机器灰盒 | F39: 制作轮式载体与组件安装外观 | G39: 制作载体、货舱档位、槽位盖板、状态灯与组件占位模型。 | H39: P0 | I39: P0-010,P2-002 | J39: A2 | K39: 12 | L39: 18 | M39: 中 | N39: 美术资源预算 | O39: 更换组件只改变对应安装位，货舱和状态灯具备清晰档位。 | P39: 已完成 | R39: B08/B11轮式载体与组件安装外观已交付
A40: P2-012 | B40: 阶段2 机器运行 | C40: G2 机器可运行 | D40: 技术美术与特效 | E40: 机器反馈 | F40: 制作移动、选中与状态基础反馈 | G40: 提供轮组运动、选中轮廓、激活灯、断电和等待表现。 | H40: P1 | I40: P2-011,P2-003,P2-008 | J40: A2 | K40: 8 | L40: 14 | M40: 中 | N40: 美术资源预算 | O40: 机器主要运行状态不依赖打开面板即可辨认。 | P40: 进行中 | R40: 程序部分已交付：选中轮廓(RegionInputModule.SetHighlight)+轮组运动(MachineNavigationMotionAdapter)；激活灯/断电/等待VFX表现待美术批次验收
...

Sheet 里程碑
A1: 阶段 | B1: 里程碑 | C1: 任务数 | D1: 最低工时 | E1: 最高工时 | F1: 阶段验收任务 | G1: 通过条件
A2: 阶段0 工程准备 | B2: G0 工程基线 | C2: =COUNTIF(开发任务!$B$2:$B$174,A2) | D2: =SUMIF(开发任务!$B$2:$B$174,A2,开发任务!$K$2:$K$174) | E2: =SUMIF(开发任务!$B$2:$B$174,A2,开发任务!$L$2:$L$174) | F2: G0-001 | G2: 从Launch进入空业务场景，输入与UI正常，实体可加载，项目表无阻塞错误且未改框架核心。
A3: 阶段1 世界与对象 | B3: G1 可交互世界 | C3: =COUNTIF(开发任务!$B$2:$B$174,A3) | D3: =SUMIF(开发任务!$B$2:$B$174,A3,开发任务!$K$2:$K$174) | E3: =SUMIF(开发任务!$B$2:$B$174,A3,开发任务!$L$2:$L$174) | F3: G1-001 | G3: 玩家能在初始区域选择三类对象、查看现场信息并预览合法建造位置。
A4: 阶段2 机器运行 | B4: G2 机器可运行 | C4: =COUNTIF(开发任务!$B$2:$B$174,A4) | D4: =SUMIF(开发任务!$B$2:$B$174,A4,开发任务!$K$2:$K$174) | E4: =SUMIF(开发任务!$B$2:$B$174,A4,开发任务!$L$2:$L$174) | F4: G2-001 | G4: 一台轮式机器可合法组装、激活、移动到作业点并在中枢显示可诊断状态。
A5: 阶段3 算法系统 | B5: G3 自动化可配置 | C5: =COUNTIF(开发任务!$B$2:$B$174,A5) | D5: =SUMIF(开发任务!$B$2:$B$174,A5,开发任务!$K$2:$K$174) | E5: =SUMIF(开发任务!$B$2:$B$174,A5,开发任务!$L$2:$L$174) | F5: G3-001 | G5: 玩家能从算法库应用模板，使机器产生可追踪任务，并安全修改参数。
A6: 阶段4 生产物流 | B6: G4 基础生产闭环 | C6: =COUNTIF(开发任务!$B$2:$B$174,A6) | D6: =SUMIF(开发任务!$B$2:$B$174,A6,开发任务!$K$2:$K$174) | E6: =SUMIF(开发任务!$B$2:$B$174,A6,开发任务!$L$2:$L$174) | F6: G4-001 | G6: 至少两类资源点可由机器自主生产、运输并正确入库，阻塞可诊断恢复。
A7: 阶段5 经济能源 | B7: G5 可持续经营 | C7: =COUNTIF(开发任务!$B$2:$B$174,A7) | D7: =SUMIF(开发任务!$B$2:$B$174,A7,开发任务!$K$2:$K$174) | E7: =SUMIF(开发任务!$B$2:$B$174,A7,开发任务!$L$2:$L$174) | F7: G5-001 | G7: 玩家可从生产获得资源，消费扩张，并从完全无燃料状态恢复最低生产。
A8: 阶段6 建造制造成长 | B8: G6 发展流程闭环 | C8: =COUNTIF(开发任务!$B$2:$B$174,A8) | D8: =SUMIF(开发任务!$B$2:$B$174,A8,开发任务!$K$2:$K$174) | E8: =SUMIF(开发任务!$B$2:$B$174,A8,开发任务!$L$2:$L$174) | F8: G6-001 | G8: 玩家能从中枢2级完成蓄电与制造教学，并在有效负载下完成供电扩张。
A9: 阶段7 存档离线 | B9: G7 状态可持续 | C9: =COUNTIF(开发任务!$B$2:$B$174,A9) | D9: =SUMIF(开发任务!$B$2:$B$174,A9,开发任务!$K$2:$K$174) | E9: =SUMIF(开发任务!$B$2:$B$174,A9,开发任务!$L$2:$L$174) | F9: G7-001 | G9: 从生产运行中退出再进入，在线与离线结果守恒且无重复奖励／动作。
A10: 阶段8 引导与版本终点 | B10: G8 第一版完成 | C10: =COUNTIF(开发任务!$B$2:$B$174,A10) | D10: =SUMIF(开发任务!$B$2:$B$174,A10,开发任务!$K$2:$K$174) | E10: =SUMIF(开发任务!$B$2:$B$174,A10,开发任务!$L$2:$L$174) | F10: G8-001 | G10: 第一版能够独立运行并由玩家读懂，正式美术通过集成验收，完成探索准备后明确结束。
A11: 并行美术0 视觉预研 | B11: ART-G0 视觉基线 | C11: =COUNTIF(开发任务!$B$2:$B$174,A11) | D11: =SUMIF(开发任务!$B$2:$B$174,A11,开发任务!$K$2:$K$174) | E11: =SUMIF(开发任务!$B$2:$B$174,A11,开发任务!$L$2:$L$174) | F11: ART-G0-001 | G11: 风格、实现路线和主工程导入接口已确认，后续资源可分专业并行生产且不需要推翻技术路线。
A12: 并行美术1 资源制作 | B12: ART-G1 资源包完成 | C12: =COUNTIF(开发任务!$B$2:$B$174,A12) | D12: =SUMIF(开发任务!$B$2:$B$174,A12,开发任务!$K$2:$K$174) | E12: =SUMIF(开发任务!$B$2:$B$174,A12,开发任务!$L$2:$L$174) | F12: ART-G1-001 | G12: 全部第一版资源通过专业验收，可按版本化导出包导入主工程。
A13: 并行美术2 导入验收 | B13: ART-G2 美术集成完成 | C13: =COUNTIF(开发任务!$B$2:$B$174,A13) | D13: =SUMIF(开发任务!$B$2:$B$174,A13,开发任务!$K$2:$K$174) | E13: =SUMIF(开发任务!$B$2:$B$174,A13,开发任务!$L$2:$L$174) | F13: ART-G2-001 | G13: 美术资源已导入主工程并通过完整流程验收，独立美术项目仍可继续迭代和重新导出。

Sheet 工作流
A1: 工作流 | B1: 任务数 | C1: 最低工时 | D1: 最高工时 | E1: 预算分类 | F1: 并行安排说明
A2: 配置与内容 | B2: =COUNTIF(开发任务!$D$2:$D$174,A2) | C2: =SUMIF(开发任务!$D$2:$D$174,A2,开发任务!$K$2:$K$174) | D2: =SUMIF(开发任务!$D$2:$D$174,A2,开发任务!$L$2:$L$174) | E2: 程序预算 | F2: 满足前置依赖后，可与同阶段其他工作流并行；同一并行组用于识别建议批次。
A3: 客户端程序 | B3: =COUNTIF(开发任务!$D$2:$D$174,A3) | C3: =SUMIF(开发任务!$D$2:$D$174,A3,开发任务!$K$2:$K$174) | D3: =SUMIF(开发任务!$D$2:$D$174,A3,开发任务!$L$2:$L$174) | E3: 程序预算 | F3: 满足前置依赖后，可与同阶段其他工作流并行；同一并行组用于识别建议批次。
A4: UI与交互 | B4: =COUNTIF(开发任务!$D$2:$D$174,A4) | C4: =SUMIF(开发任务!$D$2:$D$174,A4,开发任务!$K$2:$K$174) | D4: =SUMIF(开发任务!$D$2:$D$174,A4,开发任务!$L$2:$L$174) | E4: 程序预算 | F4: 满足前置依赖后，可与同阶段其他工作流并行；同一并行组用于识别建议批次。
A5: 灰盒与预制体 | B5: =COUNTIF(开发任务!$D$2:$D$174,A5) | C5: =SUMIF(开发任务!$D$2:$D$174,A5,开发任务!$K$2:$K$174) | D5: =SUMIF(开发任务!$D$2:$D$174,A5,开发任务!$L$2:$L$174) | E5: 美术资源预算 | F5: 可在独立美术项目中按并行组推进；代表性贯通通过后批量生产，资源完成后分批导入主工程。
A6: 集成与阶段验收 | B6: =COUNTIF(开发任务!$D$2:$D$174,A6) | C6: =SUMIF(开发任务!$D$2:$D$174,A6,开发任务!$K$2:$K$174) | D6: =SUMIF(开发任务!$D$2:$D$174,A6,开发任务!$L$2:$L$174) | E6: 程序预算 | F6: 满足前置依赖后，可与同阶段其他工作流并行；同一并行组用于识别建议批次。
A7: 技术美术与特效 | B7: =COUNTIF(开发任务!$D$2:$D$174,A7) | C7: =SUMIF(开发任务!$D$2:$D$174,A7,开发任务!$K$2:$K$174) | D7: =SUMIF(开发任务!$D$2:$D$174,A7,开发任务!$L$2:$L$174) | E7: 美术资源预算 | F7: 可在独立美术项目中按并行组推进；代表性贯通通过后批量生产，资源完成后分批导入主工程。
A8: 美术与声音资源 | B8: =COUNTIF(开发任务!$D$2:$D$174,A8) | C8: =SUMIF(开发任务!$D$2:$D$174,A8,开发任务!$K$2:$K$174) | D8: =SUMIF(开发任务!$D$2:$D$174,A8,开发任务!$L$2:$L$174) | E8: 美术资源预算 | F8: 可在独立美术项目中按并行组推进；代表性贯通通过后批量生产，资源完成后分批导入主工程。
A9: 美术方向与规范 | B9: =COUNTIF(开发任务!$D$2:$D$174,A9) | C9: =SUMIF(开发任务!$D$2:$D$174,A9,开发任务!$K$2:$K$174) | D9: =SUMIF(开发任务!$D$2:$D$174,A9,开发任务!$L$2:$L$174) | E9: 美术资源预算 | F9: 可在独立美术项目中按并行组推进；代表性贯通通过后批量生产，资源完成后分批导入主工程。
A10: 场景与环境美术 | B10: =COUNTIF(开发任务!$D$2:$D$174,A10) | C10: =SUMIF(开发任务!$D$2:$D$174,A10,开发任务!$K$2:$K$174) | D10: =SUMIF(开发任务!$D$2:$D$174,A10,开发任务!$L$2:$L$174) | E10: 美术资源预算 | F10: 可在独立美术项目中按并行组推进；代表性贯通通过后批量生产，资源完成后分批导入主工程。
A11: 3D资产与材质 | B11: =COUNTIF(开发任务!$D$2:$D$174,A11) | C11: =SUMIF(开发任务!$D$2:$D$174,A11,开发任务!$K$2:$K$174) | D11: =SUMIF(开发任务!$D$2:$D$174,A11,开发任务!$L$2:$L$174) | E11: 美术资源预算 | F11: 可在独立美术项目中按并行组推进；代表性贯通通过后批量生产，资源完成后分批导入主工程。
A12: 动画与交互动效 | B12: =COUNTIF(开发任务!$D$2:$D$174,A12) | C12: =SUMIF(开发任务!$D$2:$D$174,A12,开发任务!$K$2:$K$174) | D12: =SUMIF(开发任务!$D$2:$D$174,A12,开发任务!$L$2:$L$174) | E12: 美术资源预算 | F12: 可在独立美术项目中按并行组推进；代表性贯通通过后批量生产，资源完成后分批导入主工程。
A13: UI视觉与图标 | B13: =COUNTIF(开发任务!$D$2:$D$174,A13) | C13: =SUMIF(开发任务!$D$2:$D$174,A13,开发任务!$K$2:$K$174) | D13: =SUMIF(开发任务!$D$2:$D$174,A13,开发任务!$L$2:$L$174) | E13: 美术资源预算 | F13: 可在独立美术项目中按并行组推进；代表性贯通通过后批量生产，资源完成后分批导入主工程。
A14: 美术集成与验收 | B14: =COUNTIF(开发任务!$D$2:$D$174,A14) | C14: =SUMIF(开发任务!$D$2:$D$174,A14,开发任务!$K$2:$K$174) | D14: =SUMIF(开发任务!$D$2:$D$174,A14,开发任务!$L$2:$L$174) | E14: 美术资源预算 | F14: 可在独立美术项目中按并行组推进；代表性贯通通过后批量生产，资源完成后分批导入主工程。

Sheet 统计概览
A1: 《星际拓荒：自动纪元》第一版开发任务统计
A2: 当前项目：D:\unity\UnityProject\stellar-frontier-auto-era；框架来源：AI-Friendly-Project；工时为区间估算。
A3: 指标 | B3: 数量/最低 | C3: 最高 | D3: 说明 | E3: 校验状态 | F3: 备注
A4: 全部任务 | B4: =COUNTA(开发任务!$A$2:$A$174) | D4: 所有任务均有简短完成定义 | E4: 通过
A5: 程序预算（小时） | B5: =SUMIF(开发任务!$N$2:$N$174,"程序预算",开发任务!$K$2:$K$174) | C5: =SUMIF(开发任务!$N$2:$N$174,"程序预算",开发任务!$L$2:$L$174) | D5: =COUNTIF(开发任务!$N$2:$N$174,"程序预算")&"项" | E5: 通过
A6: 美术资源预算（小时） | B6: =SUMIF(开发任务!$N$2:$N$174,"美术资源预算",开发任务!$K$2:$K$174) | C6: =SUMIF(开发任务!$N$2:$N$174,"美术资源预算",开发任务!$L$2:$L$174) | D6: =COUNTIF(开发任务!$N$2:$N$174,"美术资源预算")&"项" | E6: 通过 | F6: 包含灰盒、正式资源与独立美术项目
A7: 合计（小时） | B7: =SUM(开发任务!$K$2:$K$174) | C7: =SUM(开发任务!$L$2:$L$174) | D7: 程序与美术资源合计 | E7: 通过
A8: 单项工时上限 | B8: =MAX(开发任务!$L$2:$L$174) | C8: 18 | D8: 任何任务最高估算不得超过18小时 | E8: 通过
A9: 依赖图 | B9: 无缺失依赖 | C9: 无循环 | D9: 任务开始前仍需确认前置任务状态 | E9: 通过

Sheet 风险
A1: 风险ID | B1: 风险 | C1: 影响 | D1: 应对措施 | E1: 检查节点
A2: R-001 | B2: 节点算法系统规模与交互复杂度被低估 | C2: 关键路径延期 | D2: 先完成最小节点集合、运行时、诊断，再扩展模板与表现。 | E2: G3
A3: R-002 | B3: 在线与离线推进结果不一致 | C3: 存档污染、资源异常 | D3: 共用确定性时间与结算入口，离线只做批量推进。 | E3: G7
A4: R-003 | B4: 系统较多导致UI信息过载 | C4: 学习成本过高 | D4: 规则按钮、分层警报、默认模板和分阶段解锁共同控制信息量。 | E4: G3/G8
A5: R-004 | B5: 个人开发并行能力有限 | C5: 任务切换成本抵消并行收益 | D5: 并行表示可独立推进，不要求同时开工；以里程碑关键路径优先。 | E5: 每阶段
A6: R-005 | B6: 正式美术阻塞功能验证 | C6: 玩法无法及时验证 | D6: 先用灰盒和可替换视觉子对象，正式资源不得改变逻辑根与锚点。 | E6: G1/G8
A7: R-006 | B7: 框架边界被业务代码侵入 | C7: 升级与维护风险 | D7: 产品代码限定在项目层，阶段门执行框架纯度审计。 | E7: G0/G8
A8: R-007 | B8: 独立美术项目与主工程接口漂移 | C8: 返工或导入失败 | D8: 先冻结比例、命名、锚点、材质和动作参数合同；每个美术验收门导入一个样例包验证。 | E8: ART-G0/G1
A9: R-008 | B9: 正式美术过晚导入导致表现问题集中暴露 | C9: 版本收口延期 | D9: 资源生产保持独立并行，但ART-G1后立即分批导入，不等待所有程序功能完成。 | E9: ART-G1/G2

Sheet 美术并行路线
A1: 美术独立并行开发路线
A2: 风格与实现路线先行，并在正式资源批量生产前完成代表性资源贯通验证；资源按场景、机器组件、建筑资源点、动画VFX和UI分批导入主工程。程序灰盒不等待正式美术，G8最终验收必须等待ART-G2。
A4: 并行阶段 | B4: 主要目标 | C4: 是否依赖主工程 | D4: 主要交付物 | E4: 验收门 | F4: 进入下一阶段条件
A5: 并行美术0 视觉预研 | B5: 确认风格、制作路线、导入规则并完成代表性资源贯通 | C5: 只依赖阶段0的框架接入与视觉合同 | D5: Art Bible、场景样片、动作矩阵、导入预设、贯通报告 | E5: ART-G0 | F5: 风格、制作路线和主工程接口均通过验证
A6: 并行美术1 资源制作 | B6: 按专业并行生产场景、模型、动画、VFX和UI资源 | C6: 否；独立项目内完成制作和专业验收 | D6: 版本化正式美术资源包 | E6: ART-G1 | F6: 资源通过Art Bible与技术规格验收；单类完成即可分批导入
A7: 并行美术2 导入验收 | B7: 按领域分批导入、绑定真实状态并完成性能与一致性收口 | C7: 是；各领域只依赖对应主工程接口 | D7: 主工程正式资源、绑定结果、性能报告 | E7: ART-G2 | F7: 完整流程通过正式美术集成验收
A9: 工作流 | B9: 任务数 | C9: 最低工时 | D9: 最高工时 | E9: 主要并行组 | F9: 说明
A10: 美术方向与规范 | B10: =COUNTIF(开发任务!$D$2:$D$174,A10) | C10: =SUMIF(开发任务!$D$2:$D$174,A10,开发任务!$K$2:$K$174) | D10: =SUMIF(开发任务!$D$2:$D$174,A10,开发任务!$L$2:$L$174) | E10: ART-RND / ART-INT | F10: 满足ART验收门和任务自身依赖后可并行；正式资源按领域完成后立即分批导入。
A11: 场景与环境美术 | B11: =COUNTIF(开发任务!$D$2:$D$174,A11) | C11: =SUMIF(开发任务!$D$2:$D$174,A11,开发任务!$K$2:$K$174) | D11: =SUMIF(开发任务!$D$2:$D$174,A11,开发任务!$L$2:$L$174) | E11: ART-RND / ART-SCENE / ART-INT | F11: 满足ART验收门和任务自身依赖后可并行；正式资源按领域完成后立即分批导入。
A12: 3D资产与材质 | B12: =COUNTIF(开发任务!$D$2:$D$174,A12) | C12: =SUMIF(开发任务!$D$2:$D$174,A12,开发任务!$K$2:$K$174) | D12: =SUMIF(开发任务!$D$2:$D$174,A12,开发任务!$L$2:$L$174) | E12: ART-RND / ART-ASSET | F12: 满足ART验收门和任务自身依赖后可并行；正式资源按领域完成后立即分批导入。
A13: 动画与交互动效 | B13: =COUNTIF(开发任务!$D$2:$D$174,A13) | C13: =SUMIF(开发任务!$D$2:$D$174,A13,开发任务!$K$2:$K$174) | D13: =SUMIF(开发任务!$D$2:$D$174,A13,开发任务!$L$2:$L$174) | E13: ART-RND / ART-MOTION | F13: 满足ART验收门和任务自身依赖后可并行；正式资源按领域完成后立即分批导入。
A14: 技术美术与特效 | B14: =COUNTIF(开发任务!$D$2:$D$174,A14) | C14: =SUMIF(开发任务!$D$2:$D$174,A14,开发任务!$K$2:$K$174) | D14: =SUMIF(开发任务!$D$2:$D$174,A14,开发任务!$L$2:$L$174) | E14: ART-VFX / 原阶段组 | F14: 满足ART验收门和任务自身依赖后可并行；正式资源按领域完成后立即分批导入。
A15: UI视觉与图标 | B15: =COUNTIF(开发任务!$D$2:$D$174,A15) | C15: =SUMIF(开发任务!$D$2:$D$174,A15,开发任务!$K$2:$K$174) | D15: =SUMIF(开发任务!$D$2:$D$174,A15,开发任务!$L$2:$L$174) | E15: ART-RND / ART-UI | F15: 满足ART验收门和任务自身依赖后可并行；正式资源按领域完成后立即分批导入。
A16: 美术集成与验收 | B16: =COUNTIF(开发任务!$D$2:$D$174,A16) | C16: =SUMIF(开发任务!$D$2:$D$174,A16,开发任务!$K$2:$K$174) | D16: =SUMIF(开发任务!$D$2:$D$174,A16,开发任务!$L$2:$L$174) | E16: ART-G0 / ART-G1 / ART-INT / ART-G2 | F16: 满足ART验收门和任务自身依赖后可并行；正式资源按领域完成后立即分批导入。
A17: 灰盒与预制体 | B17: =COUNTIF(开发任务!$D$2:$D$174,A17) | C17: =SUMIF(开发任务!$D$2:$D$174,A17,开发任务!$K$2:$K$174) | D17: =SUMIF(开发任务!$D$2:$D$174,A17,开发任务!$L$2:$L$174) | E17: 原阶段组 | F17: 满足ART验收门和任务自身依赖后可并行；正式资源按领域完成后立即分批导入。
A18: 美术与声音资源 | B18: =COUNTIF(开发任务!$D$2:$D$174,A18) | C18: =SUMIF(开发任务!$D$2:$D$174,A18,开发任务!$K$2:$K$174) | D18: =SUMIF(开发任务!$D$2:$D$174,A18,开发任务!$L$2:$L$174) | E18: 原阶段组 | F18: 满足ART验收门和任务自身依赖后可并行；正式资源按领域完成后立即分批导入。
